<?xml version="1.0" ?>
<robot name="panthera" xmlns:xacro="http://ros.org/wiki/xacro">

  <!-- links -->
  <link name="base_footprint"/>

  <joint name="base_joint" type="fixed">
    <parent link="base_footprint"/>
    <child link="base_link"/>
    <origin xyz="0.0 0.0 0.0010" rpy="0 0 0"/>
  </joint>

  <link name="base_link">
    <visual>
        <origin xyz="0 0 0" rpy="0 0 0"/>
        <geometry>
        <mesh filename="package://panthera_description/meshes/UMS5_Chassis_Cover.stl" scale="0.001 0.001 0.001"/>
        </geometry>
    </visual>
    <collision>
        <origin xyz="0 0 0" rpy="0 0 0"/>
        <geometry>
             <box size="0.002 0.002 0.002"/>
        </geometry>
    </collision>
    <inertial>
      <origin xyz="0 0 0" rpy="0 0 0"/>
      <mass value="1"/>
      <inertia ixx="0.166667" ixy="0.000000" ixz="0.000000" iyy="0.166667" iyz="0.000000" izz="0.166667"/>
    </inertial>
  </link>




  <link name="fl_steering_link">
    <visual>
      <geometry>
        <mesh filename="package://panthera_description/meshes/UMS5_Steering.stl" scale="0.001 0.001 0.001"/>
      </geometry>
      <origin xyz="0.0 0.0 0.0" rpy="0 0 0"/>
    </visual>
    <collision>
      <geometry>
        <mesh filename="package://panthera_description/meshes/UMS5_Steering.stl" scale="0.0001 0.0001 0.0001"/>
      </geometry>
      <origin xyz="0.0 0.0 0.0" rpy="0 0 0"/>
    </collision>
    <inertial>
      <origin rpy="0 0 0" xyz="0 0 0"/>
      <mass value="1"/>
      <inertia ixx="0.166667" ixy="0.000000" ixz="0.000000" iyy="0.166667" iyz="0.000000" izz="0.166667"/>
    </inertial>
  </link>

  <link name="fr_steering_link">
    <visual>
      <geometry>
        <mesh filename="package://panthera_description/meshes/UMS5_Steering.stl" scale="0.001 0.001 0.001"/>
      </geometry>
      <origin xyz="0.0 0.0 0.0" rpy="0 0 0"/>
    </visual>
    <collision>
      <geometry>
        <mesh filename="package://panthera_description/meshes/UMS5_Steering.stl" scale="0.0001 0.0001 0.0001"/>
      </geometry>
      <origin xyz="0.0 0.0 0.0" rpy="0 0 0"/>
    </collision>
    <inertial>
      <origin rpy="0 0 0" xyz="0 0 0"/>
      <mass value="1"/>
      <inertia ixx="0.166667" ixy="0.000000" ixz="0.000000" iyy="0.166667" iyz="0.000000" izz="0.166667"/>
    </inertial>
  </link>

  <link name="rl_steering_link">
    <visual>
      <geometry>
        <mesh filename="package://panthera_description/meshes/UMS5_Steering.stl" scale="0.001 0.001 0.001"/>
      </geometry>
      <origin xyz="0.0 0.0 0.0" rpy="0 0 0"/>
    </visual>
    <collision>
      <geometry>
        <mesh filename="package://panthera_description/meshes/UMS5_Steering.stl" scale="0.0001 0.0001 0.0001"/>
      </geometry>
      <origin xyz="0.0 0.0 0.0" rpy="0 0 0"/>
    </collision>
    <inertial>
      <origin rpy="0 0 0" xyz="0 0 0"/>
      <mass value="1"/>
      <inertia ixx="0.166667" ixy="0.000000" ixz="0.000000" iyy="0.166667" iyz="0.000000" izz="0.166667"/>
    </inertial>
  </link>

  <link name="rr_steering_link">
    <visual>
      <geometry>
        <mesh filename="package://panthera_description/meshes/UMS5_Steering.stl" scale="0.001 0.001 0.001"/>
      </geometry>
      <origin xyz="0.0 0.0 0.0" rpy="0 0 0"/>
    </visual>
    <collision>
      <geometry>
        <mesh filename="package://panthera_description/meshes/UMS5_Steering.stl" scale="0.0001 0.0001 0.0001"/>
      </geometry>
      <origin xyz="0.0 0.0 0.0" rpy="0 0 0"/>
    </collision>
    <inertial>
      <origin rpy="0 0 0" xyz="0 0 0"/>
      <mass value="1"/>
      <inertia ixx="0.166667" ixy="0.000000" ixz="0.000000" iyy="0.166667" iyz="0.000000" izz="0.166667"/>
    </inertial>
  </link>

  <link name="fl_wheel_link">
    <visual>
      <geometry>
        <mesh filename="package://panthera_description/meshes/UMS5_Wheel_15_inch.stl" scale="0.001 0.001 0.001"/>
      </geometry>
      <origin xyz="-0.2 -0.01 -0.2" rpy="0 0 0"/>
    </visual>
    <collision>
      <geometry>
        <cylinder length="0.1" radius="0.175"/>
      </geometry>
      <origin xyz="0.0 -0.01 0.0" rpy="0 1.57 0"/>
    </collision>
    <inertial>
      <origin rpy="0 -0.2 0" xyz="0 0 0"/>
      <mass value="1"/>
      <inertia ixx="0.166667" ixy="0.000000" ixz="0.000000" iyy="0.166667" iyz="0.000000" izz="0.166667"/>
    </inertial>
  </link>

  <link name="rl_wheel_link">
    <visual>
      <geometry>
        <mesh filename="package://panthera_description/meshes/UMS5_Wheel_15_inch.stl" scale="0.001 0.001 0.001"/>
      </geometry>
      <origin xyz="-0.2 -0.01 -0.2" rpy="0 0 0"/>
    </visual>
    <collision>
      <geometry>
                <cylinder length="0.1" radius="0.175"/>
      </geometry>
      <origin xyz="0.0 -0.01 0.0" rpy="0 1.57 0"/>
    </collision>
    <inertial>
      <origin rpy="0 -0.2 0" xyz="0 0 0"/>
      <mass value="1"/>
      <inertia ixx="0.166667" ixy="0.000000" ixz="0.000000" iyy="0.166667" iyz="0.000000" izz="0.166667"/>
    </inertial>
  </link>

  <link name="fr_wheel_link">
    <visual>
      <geometry>
        <mesh filename="package://panthera_description/meshes/UMS5_Wheel_15_inch.stl" scale="0.001 0.001 0.001"/>
      </geometry>
      <origin xyz="-0.2 0 -0.2" rpy="0 0 0"/>
    </visual>
    <collision>
      <geometry>
         <cylinder length="0.1" radius="0.175"/>
      </geometry>
      <origin xyz="0.0 0.0 0.0" rpy="0 1.57 0"/>
    </collision>
    <inertial>
      <origin rpy="0 0 0" xyz="0 0 0"/>
      <mass value="1"/>
      <inertia ixx="0.166667" ixy="0.000000" ixz="0.000000" iyy="0.166667" iyz="0.000000" izz="0.166667"/>
    </inertial>
  </link>

  <link name="rr_wheel_link">
    <visual>
      <geometry>
        <mesh filename="package://panthera_description/meshes/UMS5_Wheel_15_inch.stl" scale="0.001 0.001 0.001"/>
      </geometry>
      <origin xyz="-0.2 0 -0.2" rpy="0 0 0"/>
    </visual>
    <collision>
      <geometry>
                <cylinder length="0.1" radius="0.175"/>
      </geometry>
      <origin xyz="0.0 0.0 0.0" rpy="0 1.57 0"/>
    </collision>
    <inertial>
      <origin rpy="0 0 0" xyz="0 0 0"/>
      <mass value="1"/>
      <inertia ixx="0.166667" ixy="0.000000" ixz="0.000000" iyy="0.166667" iyz="0.000000" izz="0.166667"/>
    </inertial>
  </link>

  <!-- joints -->




  <joint name="fl_steering_link_joint" type="revolute">
    <axis xyz="0 0 1"/>
    <limit effort="1000.0" lower="-1.571" upper="1.571" velocity="0.5"/>
    <origin xyz="0.724 0.250 0.05" rpy="0 0 0"/>
    <parent link="base_link"/>
    <child link="fl_steering_link"/>
  </joint>

  <joint name="fr_steering_link_joint" type="revolute">
    <axis xyz="0 0 1"/>
    <limit effort="1000.0" lower="-1.571" upper="1.571" velocity="0.5"/>
    <origin xyz="0.724 -0.250 0.05" rpy="0 0 0"/>
    <parent link="base_link"/>
    <child link="fr_steering_link"/>
  </joint>

  <joint name="rl_steering_link_joint" type="revolute">
    <axis xyz="0 0 1"/>
    <limit effort="1000.0" lower="-1.571" upper="1.571" velocity="0.5"/>
    <origin xyz="-0.29 0.250 0.01" rpy="0 0 0"/>
    <parent link="base_link"/>
    <child link="rl_steering_link"/>
  </joint>

  <joint name="rr_steering_link_joint" type="revolute">
    <axis xyz="0 0 1"/>
    <limit effort="1000.0" lower="-1.571" upper="1.571" velocity="0.5"/>
    <origin xyz="-0.29 -0.250 0.01" rpy="0 0 0"/>
    <parent link="base_link"/>
    <child link="rr_steering_link"/>
  </joint>

  <joint name="fl_wheel_link_joint" type="continuous">
    <axis xyz="1 0 0"/>
    <origin xyz="0 0 0" rpy="0 0 1.57"/>
    <parent link="fl_steering_link"/>
    <child link="fl_wheel_link"/>
  </joint>

  <joint name="rl_wheel_link_joint" type="continuous">
    <axis xyz="1 0 0"/>
    <origin xyz="0 0 0" rpy="0 0 1.57"/>
    <parent link="rl_steering_link"/>
    <child link="rl_wheel_link"/>
  </joint>

  <joint name="fr_wheel_link_joint" type="continuous">
    <axis xyz="1 0 0"/>
    <origin xyz="0 0 0" rpy="0 0 1.57"/>
    <parent link="fr_steering_link"/>
    <child link="fr_wheel_link"/>
  </joint>

  <joint name="rr_wheel_link_joint" type="continuous">
    <axis xyz="1 0 0"/>
    <origin xyz="0 0 0" rpy="0 0 1.57"/>
    <parent link="rr_steering_link"/>
    <child link="rr_wheel_link"/>
  </joint>

  <!-- gazebo related -->

  <!-- materials -->

  <gazebo reference="base_link">
    <material>Gazebo/Green</material>
  </gazebo>

  <gazebo reference="fl_steering_link">
    <material>Gazebo/Grey</material>
  </gazebo>

  <gazebo reference="fr_steering_link">
    <material>Gazebo/Grey</material>
  </gazebo>

  <gazebo reference="rl_steering_link">
    <material>Gazebo/Grey</material>
  </gazebo>

  <gazebo reference="rr_steering_link">
    <material>Gazebo/Grey</material>
  </gazebo>

  <gazebo reference="fl_wheel_link">
    <mu1 value="0.001" />
    <mu2 value="0.001" />
    <kp  value="1000000.0" />
    <kd  value="1.0" />
    <material>Gazebo/Black</material>
  </gazebo>

  <gazebo reference="fr_wheel_link">
    <mu1 value="0.001" />
    <mu2 value="0.001" />
    <kp  value="1000000.0" />
    <kd  value="1.0" />
    <material>Gazebo/Black</material>
  </gazebo>

  <gazebo reference="rl_wheel_link">
    <mu1 value="0.001" />
    <mu2 value="0.001" />
    <kp  value="1000000.0" />
    <kd  value="1.0" />
    <material>Gazebo/Black</material>
  </gazebo>

  <gazebo reference="rr_wheel_link">
    <mu1 value="0.001" />
    <mu2 value="0.001" />
    <kp  value="1000000.0" />
    <kd  value="1.0" />
    <material>Gazebo/Black</material>
  </gazebo>



  <!-- controllers -->
  <gazebo>
    <plugin name="gazebo_ros_control" filename="libgazebo_ros_control.so">
      <robotNamespace>/panthera_robot</robotNamespace>
      <robotSimType>gazebo_ros_control/DefaultRobotHWSim</robotSimType>

    </plugin>
  </gazebo>



  <transmission name="fl_steering_trans">
    <type>transmission_interface/SimpleTransmission</type>
    <actuator name="fl_steering_motor">
      <hardwareInterface>PositionJointInterface</hardwareInterface>
      <mechanicalReduction>1</mechanicalReduction>
    </actuator>
    <joint name="fl_steering_link_joint">
      <hardwareInterface>hardware_interface/PositionJointInterface</hardwareInterface>
    </joint>
  </transmission>

  <transmission name="fr_steering_trans">
    <type>transmission_interface/SimpleTransmission</type>
    <actuator name="fr_steering_motor">
      <hardwareInterface>PositionJointInterface</hardwareInterface>
      <mechanicalReduction>1</mechanicalReduction>
    </actuator>
    <joint name="fr_steering_link_joint">
      <hardwareInterface>hardware_interface/PositionJointInterface</hardwareInterface>
    </joint>
  </transmission>

  <transmission name="rl_steering_trans">
    <type>transmission_interface/SimpleTransmission</type>
    <actuator name="rl_steering_motor">
      <hardwareInterface>PositionJointInterface</hardwareInterface>
      <mechanicalReduction>1</mechanicalReduction>
    </actuator>
    <joint name="rl_steering_link_joint">
      <hardwareInterface>hardware_interface/PositionJointInterface</hardwareInterface>
    </joint>
  </transmission>

  <transmission name="rr_steering_trans">
    <type>transmission_interface/SimpleTransmission</type>
    <actuator name="rr_steering_motor">
      <hardwareInterface>PositionJointInterface</hardwareInterface>
      <mechanicalReduction>1</mechanicalReduction>
    </actuator>
    <joint name="rr_steering_link_joint">
      <hardwareInterface>hardware_interface/PositionJointInterface</hardwareInterface>
    </joint>
  </transmission>

  <transmission name="fl_wheel_trans">
    <type>transmission_interface/SimpleTransmission</type>
    <actuator name="fl_wheel_motor">
      <hardwareInterface>VelocityJointInterface</hardwareInterface>
      <mechanicalReduction>1</mechanicalReduction>
    </actuator>
    <joint name="fl_wheel_link_joint">
      <hardwareInterface>hardware_interface/VelocityJointInterface</hardwareInterface>
    </joint>
  </transmission>

  <transmission name="fr_wheel_trans">
    <type>transmission_interface/SimpleTransmission</type>
    <actuator name="fr_wheel_motor">
      <hardwareInterface>VelocityJointInterface</hardwareInterface>
      <mechanicalReduction>1</mechanicalReduction>
    </actuator>
    <joint name="fr_wheel_link_joint">
      <hardwareInterface>hardware_interface/VelocityJointInterface</hardwareInterface>
    </joint>
  </transmission>

  <transmission name="rl_wheel_trans">
    <type>transmission_interface/SimpleTransmission</type>
    <actuator name="rl_wheel_motor">
      <hardwareInterface>VelocityJointInterface</hardwareInterface>
      <mechanicalReduction>1</mechanicalReduction>
    </actuator>
    <joint name="rl_wheel_link_joint">
      <hardwareInterface>hardware_interface/VelocityJointInterface</hardwareInterface>
    </joint>
  </transmission>

  <transmission name="rr_wheel_trans">
    <type>transmission_interface/SimpleTransmission</type>
    <actuator name="rr_wheel_motor">
      <hardwareInterface>VelocityJointInterface</hardwareInterface>
      <mechanicalReduction>1</mechanicalReduction>
    </actuator>
    <joint name="rr_wheel_link_joint">
      <hardwareInterface>hardware_interface/VelocityJointInterface</hardwareInterface>
    </joint>
  </transmission>

</robot>
